<?xml version="1.0"?>


<robot xmlns:xacro="http://www.ros.org/wiki/xacro" name="iiwa7_gripper">
<xacro:macro name="gripper" params="prefix reflect">


    <!-- gripper -->
    <link name="${prefix}_gripper">
      <visual>
        <origin rpy="${(reflect-1)/2*pi} 0 0" xyz="0 0 0"/>
        <geometry>
          <mesh filename="package://urdf_tutorial/meshes/l_finger.dae"/>
        </geometry>
      </visual>
      <collision>
        <geometry>
          <mesh filename="package://urdf_tutorial/meshes/l_finger.dae"/>
        </geometry>
        <origin rpy="${(reflect-1)/2*pi} 0 0" xyz="0 0 0"/>
      </collision>
      <xacro:default_inertial mass="0.05"/>
    </link>

     <!-- gripper joint with base-->
    <joint name="${prefix}_gripper_joint" type="revolute">
      <axis xyz="0 0 ${reflect}"/>
      <limit effort="100.0" lower="0.0" upper="0.548" velocity="0.5"/>
      <origin rpy="0 ${-pi/2} 0" xyz="0 ${reflect*0.01} 0.045"/>
      <parent link="$(arg robot_name)_link_7"/>
      <child link="${prefix}_gripper"/>
    </joint>

    <!-- gripper tip-->
    <link name="${prefix}_tip">
      <visual>
        <origin rpy="${(reflect-1)/2*pi} 0 0" xyz="0.09137 0.00495 0"/>
        <geometry>
          <mesh filename="package://urdf_tutorial/meshes/l_finger_tip.dae"/>
        </geometry>
      </visual>
      <collision>
        <geometry>
          <mesh filename="package://urdf_tutorial/meshes/l_finger_tip.dae"/>
        </geometry>
        <origin rpy="${(reflect-1)/2*pi} 0 0" xyz="0.09137 0.00495 0"/>
      </collision>
      <xacro:default_inertial mass="0.05"/>
    </link>

    <!--Gripper to tip joint-->
    <joint name="${prefix}_tip_joint" type="fixed">
      <parent link="${prefix}_gripper"/>
      <child link="${prefix}_tip"/>
    </joint> 

<gazebo reference="left_gripper">
    <gravity>true</gravity>
    <sensor name="imu_sensor" type="imu">
      <always_on>true</always_on>
      <update_rate>100</update_rate>
      <visualize>true</visualize>
      <topic>__default_topic__</topic>
      <plugin filename="libgazebo_ros_imu_sensor.so" name="imu_plugin">
        <topicName>imu</topicName>
        <bodyName>left_gripper</bodyName>
        <updateRateHZ>10.0</updateRateHZ>
        <gaussianNoise>0.0</gaussianNoise>
        <xyzOffset>0 0 0</xyzOffset>
        <rpyOffset>0 0 0</rpyOffset>
        <frameName>left_gripper</frameName>
      </plugin>
      <pose>0 0 0 0 0 0</pose>
    </sensor>
  </gazebo>

<gazebo reference="right_gripper">
    <sensor type="gpu_ray" name="head_hokuyo_sensor">
      <pose>0 0 0 0 0 0</pose>
      <visualize>false</visualize>
      <update_rate>40</update_rate>
      <ray>
        <scan>
          <horizontal>
            <samples>720</samples>
            <resolution>1</resolution>
            <min_angle>-1.570796</min_angle>
            <max_angle>1.570796</max_angle>
          </horizontal>
        </scan>
        <range>
          <min>0.10</min>
          <max>30.0</max>
          <resolution>0.01</resolution>
        </range>
        <noise>
          <type>gaussian</type>
          <!-- Noise parameters based on published spec for Hokuyo laser
               achieving "+-30mm" accuracy at range < 10m.  A mean of 0.0m and
               stddev of 0.01m will put 99.7% of samples within 0.03m of the true
               reading. -->
          <mean>0.0</mean>
          <stddev>0.01</stddev>
        </noise>
      </ray>
      <plugin name="gazebo_ros_head_hokuyo_controller" filename="libgazebo_ros_gpu_laser.so">
        <topicName>/rrbot/laser/scan</topicName>
        <frameName>right_gripper</frameName>
      </plugin>
    </sensor>
  </gazebo>




  </xacro:macro>

  <xacro:gripper prefix="left" reflect="1" />
  <xacro:gripper prefix="right" reflect="-1" />
  </robot>
